<?xml version="1.0"?>
<robot name="phoenix">

<!-- Base footprint -->
    <link name="base_footprint"/>
    
<!--Rear Axle Link and Joint-->
    <link name="rear_axle">
        <visual>
            <origin rpy="0 0 0" xyz="0 0 0" />
            <geometry>
                <box size="0.00001 0.0000001 0.000001"/>
            </geometry>
        </visual>
        <inertial>
            <origin xyz="0 0 0" rpy="0 0 0"/>
            <mass value="0.001"/>
            <inertia
                ixx="7.6E-07" ixy="0.0" ixz="0.0"
                iyy="7.6E-07" iyz="0.0"
                izz="0.000001"/>
        </inertial>
    </link>

    <joint name="base_footprint_to_rear_axle" type="fixed">
        <origin rpy="0 0 0" xyz="0 0 0.127"/>
        <parent link="base_footprint"/>
        <child link="rear_axle"/>
    </joint>

    <link name="physical_rear_axle">
        <visual>
            <origin rpy="0 0 0" xyz="0 0 0" />
            <geometry>
                <cylinder length="0.9398" radius="0.050"/>
            </geometry>
        </visual>
        <inertial>
            <origin xyz="0 0 0" rpy="0 0 0"/>
            <mass value="10"/>
            <inertia
                ixx="0.74227005" ixy="0.0" ixz="0.0"
                iyy="0.74227005" iyz="0.0"
                izz="0.012500001"/>
        </inertial>
    </link>

    <joint name="rear_axle_to_physical_rear_axle" type="continuous">
        <origin rpy="1.5708 0 3.14159" xyz="0 0 0"/>
        <parent link="rear_axle"/>
        <child link="physical_rear_axle"/>
        <axis xyz="0 0 1"/>
    </joint>


<!--Chassis link and joint -->    
    <link name="base_link">
        <visual>
            <origin rpy="0 0 0" xyz="0 0 0" />
            <geometry>
                <box size="1.3967 0.8382 0.1"/>
            </geometry>
        </visual>
        <collision>
            <origin rpy="0 0 0" xyz="0 0 0" />
            <geometry>
                <box size="1.3967 0.8382 0.1"/>
            </geometry>
        </collision>
        <inertial>
            <origin xyz="0 0 0" rpy="0 0 0"/>
            <mass value="90"/>
            <inertia
                ixx="5.3443437" ixy="0.0" ixz="0.0"
                iyy="14.705783" iyz="0.0"
                izz="14.705781675"/>
        </inertial>
    </link>
    
    <joint name="rear_axle_to_base_link" type="fixed">
        <origin rpy="0 0 0" xyz="0.82535 0 0"/>
        <parent link="rear_axle"/>
        <child link="base_link"/>
    </joint>
    
    
<!-- Wheel links and joints -->
    
    <!-- Left wheel link and joint -->
    <link name="left_front_wheel">
        <visual>
            <origin rpy="1.5708 0 0" xyz="0 0 0" />
            <geometry>
                <cylinder length="0.1143" radius="0.12065"/>
            </geometry>
        </visual>
        <collision>
            <origin rpy="1.5708 0 0" xyz="0 0 0" />
            <geometry>
                <cylinder length="0.1143" radius="0.12065"/>
            </geometry>
        </collision>
        <inertial>
            <origin xyz="0 0 0" rpy="1.5708 0 0"/>
            <mass value="1.1"/>
            <inertia
                ixx="0.0052005947" ixy="0.0" ixz="0.0"
                iyy="0.0052005947" iyz="0.0"
                izz="0.008006033"/>
        </inertial>
    </link>

    <!-- The joint where the left wheel pivots about -->
    <link name="left_front_wheel_rack">
    <!-- These visuals are needed, else gazebo crashes -->
    <visual>
            <origin rpy="1.5708 0 0" xyz="0 0 0" />
            <geometry>
                <box size="0.00001 0.0000001 0.000001"/>
            </geometry>
        </visual>
        <inertial>
            <origin xyz="0 0 0" rpy="1.5708 0 0"/>
            <mass value="0.001"/>
            <inertia
                ixx="7.6E-07" ixy="0.0" ixz="0.0"
                iyy="7.6E-07" iyz="0.0"
                izz="0.000001"/>
        </inertial>
    </link>

    <joint name="left_front_wheel_steer" type="revolute">
        <origin rpy="0 0 0" xyz="1.03505 0.6477 0"/>
        <parent link="rear_axle"/>
        <child link="left_front_wheel_rack"/>
        <axis xyz="0 0 1"/>
        <limit lower="-0.3499" upper="+0.5236" velocity="3.141" effort="25"/>
    </joint>
    
    <joint name="left_front_wheel_rack_to_wheel" type="continuous">
        <origin rpy="0 0 0" xyz="0 -0.00001 0"/>
        <parent link="left_front_wheel_rack"/>
        <child link="left_front_wheel"/>
        <axis xyz="0 1 0"/>
    </joint>
    
    <!-- Right wheel link and joint -->
    <link name="right_front_wheel">
        <visual>
            <origin rpy="1.5708 0 0" xyz="0 0 0" />
            <geometry>
               <cylinder length="0.1143" radius="0.12065"/>
            </geometry>
        </visual>
        <collision>
            <origin rpy="1.5708 0 0" xyz="0 0 0" />
            <geometry>
                <cylinder length="0.1143" radius="0.12065"/>
            </geometry>
        </collision>
        <inertial>
            <origin xyz="0 0 0" rpy="1.5708 0 0"/>
            <mass value="1.1"/>
            <inertia
                ixx="0.0052005947" ixy="0.0" ixz="0.0"
                iyy="0.0052005947" iyz="0.0"
                izz="0.008006033"/>
        </inertial>
    </link>

    <!-- The joint where the right wheel pivots about -->
    <link name="right_front_wheel_rack">
    <!-- These visuals are needed, else gazebo crashes -->
    <visual>
        <origin rpy="1.5708 0 0" xyz="0 0 0" />
            <geometry>
                <box size="0.00001 0.0000001 0.000001"/>
            </geometry>
        </visual>
        <inertial>
            <origin xyz="0 0 0" rpy="1.5708 0 0"/>
            <mass value="0.001"/>
            <inertia
                ixx="7.6E-07" ixy="0.0" ixz="0.0"
                iyy="7.6E-07" iyz="0.0"
                izz="0.000001"/>
        </inertial>
    </link>
    
    <joint name="right_front_wheel_steer" type="revolute">
        <origin rpy="0 0 0" xyz="1.03505 -0.6477 0"/>
        <parent link="rear_axle"/>
        <child link="right_front_wheel_rack"/>
        <axis xyz="0 0 1"/>
        <limit lower="-0.3499" upper="+0.5236" velocity="3.141" effort="25"/>
    </joint> 
    
    <joint name="right_front_wheel_rack_to_wheel" type="continuous">
        <origin rpy="0 0 0" xyz="0 -0.00001 0"/>
        <parent link="right_front_wheel_rack"/>
        <child link="right_front_wheel"/>
        <axis xyz="0 1 0"/>
    </joint> 

    <!--Rear Wheels -->
    <link name="left_rear_wheel">
        <visual>
            <origin rpy="0 0 0" xyz="0 0 0" />
            <geometry>
                <cylinder length="0.2032" radius="0.127"/>
            </geometry>
        </visual>
        <collision>
            <origin rpy="0 0 0" xyz="0 0 0" />
            <geometry>
                <cylinder length="0.2032" radius="0.127"/>
            </geometry>
        </collision>
        <inertia>
            <origin xyz="0 0 0" rpy="1.5708 0 0"/>
            <mass value="1.5"/>
            <inertia
                ixx="0.011209655" ixy="0.0" ixz="0.0"
                iyy="0.011209655" iyz="0.0"
                izz="0.01209675"/>
        </inertia>
    </link>

    <joint name="left_rear_wheel_to_physical_rear_axle" type="fixed">
        <origin rpy="0 0 0" xyz="0 0 -0.6371"/>
        <parent link="physical_rear_axle"/>
        <child link="left_rear_wheel"/>
    </joint>

    <link name="right_rear_wheel">
        <visual>
            <origin rpy="0 0 0" xyz="0 0 0" />
            <geometry>
                <cylinder length="0.2032" radius="0.127"/>
            </geometry>
        </visual>
        <collision>
            <origin rpy="0 0 0" xyz="0 0 0" />
            <geometry>
                <cylinder length="0.2032" radius="0.127"/>
            </geometry>
        </collision>
        <inertia>
            <origin xyz="0 0 0" rpy="1.5708 0 0"/>
            <mass value="1.5"/>
            <inertia
                ixx="0.011209655" ixy="0.0" ixz="0.0"
                iyy="0.011209655" iyz="0.0"
                izz="0.01209675"/>
        </inertia>
    </link>

    <joint name="right_rear_wheel_to_physical_rear_axle" type="fixed">
        <origin rpy="0 0 0" xyz="0 0 0.6371"/>
        <parent link="physical_rear_axle"/>
        <child link="right_rear_wheel"/>
    </joint>
    
<!-- Sensors -->

<link name="mid_cam_link">
    <visual>
        <origin rpy="0 0 0" xyz="0 0 0" />
        <geometry>
            <box size="0.02 0.05 0.02"/>
        </geometry>
    </visual>
    <collision>
        <origin rpy="0 0 0" xyz="0 0 0" />
        <geometry>
            <box size="0.02 0.05 0.02"/>
        </geometry>
    </collision>
    <inertial>
        <origin xyz="0 0 0" rpy="0 0 0"/>
        <mass value="0.1"/>
        <inertia
            ixx="0.000315771" ixy="0.0" ixz="0.0"
            iyy="0.00266963" iyz="0.0"
            izz="0.0"/>
    </inertial>
</link>
<joint name="mid_cam_to_rear_axle" type="fixed">
    <origin rpy="0 0 0" xyz="1.05 0 0.4"/>
    <parent link="rear_axle"/>
    <child link="mid_cam_link"/>
</joint>

<!-- Camera in the sky for analysing the good areas -->
<link name="sky_cam_link">
    <visual>
        <origin rpy="0 0 0" xyz="0 0 0" />
        <geometry>
            <box size="0.02 0.05 0.02"/>
        </geometry>
    </visual>
    <inertial>
        <origin xyz="0 0 0" rpy="0 0 0"/>
        <mass value="0.1"/>
        <inertia
            ixx="0.000315771" ixy="0.0" ixz="0.0"
            iyy="0.00266963" iyz="0.0"
            izz="0.0"/>
    </inertial>
</link>
<joint name="sky_cam_to_base_link" type="fixed">
    <origin rpy="0 1.57 0" xyz="0 0 20.5"/>
    <parent link="base_footprint"/>
    <child link="sky_cam_link"/>
</joint>

<!-- Gazebo Plugins -->
    
  <gazebo>
      <plugin filename="gz-sim-imu-system"
              name="gz::sim::systems::Imu">
      </plugin>

    <plugin filename="gz-sim-ackermann-steering-system"
    name="gz::sim::systems::AckermannSteering">
      <left_steering_joint>left_front_wheel_steer</left_steering_joint>
      <right_steering_joint>right_front_wheel_steer</right_steering_joint>
        <left_joint>rear_axle_to_physical_rear_axle</left_joint>
        <right_joint>rear_axle_to_physical_rear_axle</right_joint>

        <min_velocity>-13</min_velocity>
        <max_velocity>13</max_velocity>
        <min_acceleration>-3</min_acceleration>
        <max_acceleration>4</max_acceleration>

        <wheel_separation>0.94</wheel_separation>
      <wheel_radius>0.12065</wheel_radius>
      <wheel_base>1.08</wheel_base>
        <odom_publish_frequency>20</odom_publish_frequency>
    </plugin>
  </gazebo>
  
    <gazebo reference="mid_cam_link">
        <sensor name="mid_cam_link" type="rgbd_camera">
          <camera>
            <horizontal_fov>1.65806</horizontal_fov>
            <image>
              <width>640</width>
              <height>360</height>
            </image>
            <clip>
              <near>0.1</near>
              <far>100</far>
            </clip>
              <depth_camera>
                  <clip>
                      <near>0.6</near>
                      <far>10</far>
                  </clip>
              </depth_camera>
          </camera>
          <always_on>1</always_on>
          <update_rate>30</update_rate>
          <visualize>true</visualize>
          <topic>mid_rgbd_camera</topic>
          <enable_metrics>true</enable_metrics>
            <gz_frame_id>mid_cam_link</gz_frame_id>
        </sensor>
  </gazebo>

  <!-- Simulate OAK-D IMU -->
  <gazebo reference="mid_cam_link">
      <sensor name="imu_sensor" type="imu">
          <always_on>1</always_on>
          <update_rate>60</update_rate>
          <visualize>false</visualize>
          <topic>mid_rgbd_camera_imu</topic>
          <gz_frame_id>mid_cam_link</gz_frame_id>
<!--          <imu>-->
<!--              <angular_velocity>-->
<!--                  <x>-->
<!--                      <noise type="gaussian">-->
<!--                          <mean>0.0</mean>-->
<!--                          <stddev>0.1</stddev>-->
<!--                      </noise>-->
<!--                  </x>-->
<!--                  <y>-->
<!--                      <noise type="gaussian">-->
<!--                          <mean>0.0</mean>-->
<!--                          <stddev>0.1</stddev>-->
<!--                      </noise>-->
<!--                  </y>-->
<!--                  <z>-->
<!--                      <noise type="gaussian">-->
<!--                          <mean>0.0</mean>-->
<!--                          <stddev>0.1</stddev>-->
<!--                      </noise>-->
<!--                  </z>-->
<!--              </angular_velocity>-->
<!--              <linear_acceleration>-->
<!--                  <x>-->
<!--                      <noise type="gaussian">-->
<!--                          <mean>0.0</mean>-->
<!--                          <stddev>0.1</stddev>-->
<!--                      </noise>-->
<!--                  </x>-->
<!--                  <y>-->
<!--                      <noise type="gaussian">-->
<!--                          <mean>0.0</mean>-->
<!--                          <stddev>0.1</stddev>-->
<!--                      </noise>-->
<!--                  </y>-->
<!--                  <z>-->
<!--                      <noise type="gaussian">-->
<!--                          <mean>0.0</mean>-->
<!--                          <stddev>0.1</stddev>-->
<!--                      </noise>-->
<!--                  </z>-->
<!--              </linear_acceleration>-->
<!--          </imu>-->
      </sensor>
  </gazebo>

<!--  <gazebo reference="sky_cam_link"> TODO enable this if using score overlay-->
<!--        <sensor name="sky_cam_link" type="rgbd_camera">-->
<!--          <camera>-->
<!--            <horizontal_fov>1.047</horizontal_fov>-->
<!--            <image>-->
<!--              <width>320</width>-->
<!--              <height>240</height>-->
<!--            </image>-->
<!--            <clip>-->
<!--              <near>0.1</near>-->
<!--              <far>100</far>-->
<!--            </clip>-->
<!--          </camera>-->
<!--          <always_on>1</always_on>-->
<!--          <update_rate>10</update_rate>-->
<!--          <visualize>true</visualize>-->
<!--          <topic>sky_rgbd_camera</topic>-->
<!--          <enable_metrics>true</enable_metrics>-->
<!--        </sensor>-->
<!--  </gazebo>-->
</robot>
            
